Workbook

Sheet Summary
A1: Intel Corporation: Model Summary
A2: $ millions except per share. Active scenario: | B2: =Scenarios!B2 -> Base
A3: Model checks: | B3: =Checks!B14 -> ALL CHECKS PASS
A5: Key Financials | B5: ='Income Statement'!D1 -> FY2025 | C5: ='Income Statement'!E1 -> FY2026E | D5: ='Income Statement'!F1 -> FY2027E | E5: ='Income Statement'!G1 -> FY2028E | F5: ='Income Statement'!H1 -> FY2029E | G5: ='Income Statement'!I1 -> FY2030E
A6: Revenue | B6: ='Income Statement'!D2 -> 52853 | C6: ='Income Statement'!E2 -> 60780.95 | D6: ='Income Statement'!F2 -> 68074.664 | E6: ='Income Statement'!G2 -> 74882.13 | F6: ='Income Statement'!H2 -> 80872.701 | G6: ='Income Statement'!I2 -> 85725.063
A7: Operating income | B7: ='Income Statement'!D9 -> -2214 | C7: ='Income Statement'!E9 -> -1784.381 | D7: ='Income Statement'!F9 -> 2244.1065 | E7: ='Income Statement'!G9 -> 5739.3917 | F7: ='Income Statement'!H9 -> 8395.9971 | G7: ='Income Statement'!I9 -> 9787.0075
A8: Net income attributable to Intel | B8: ='Income Statement'!D16 -> -267 | C8: ='Income Statement'!E16 -> -1501.922 | D8: ='Income Statement'!F16 -> 1715.3319 | E8: ='Income Statement'!G16 -> 4528.2874 | F8: ='Income Statement'!H16 -> 6774.9593 | G8: ='Income Statement'!I16 -> 8105.147
A9: EPS, diluted ($) | B9: ='Income Statement'!D18 -> -0.06 | C9: ='Income Statement'!E18 -> -0.29924905 | D9: ='Income Statement'!F18 -> 0.33838584 | E9: ='Income Statement'!G18 -> 0.88445682 | F9: ='Income Statement'!H18 -> 1.310171 | G9: ='Income Statement'!I18 -> 1.5518895
A10: Free cash flow | C10: =Payback!E6 -> 1368.6194 | D10: =Payback!F6 -> 2490.9791 | E10: =Payback!G6 -> 5503.8848 | F10: =Payback!H6 -> 8444.9041 | G10: =Payback!I6 -> 9940.1581
A11: Debt / EBITDA (x) | C11: ='Credit Ratios'!E9 -> 4.2723891 | D11: ='Credit Ratios'!F9 -> 2.9738411 | E11: ='Credit Ratios'!G9 -> 2.3098283 | F11: ='Credit Ratios'!H9 -> 1.9280898 | G11: ='Credit Ratios'!I9 -> 1.7458019
A12: Cash and cash equivalents | B12: ='Balance Sheet'!D4 -> 14265 | C12: ='Balance Sheet'!E4 -> 14383.619 | D12: ='Balance Sheet'!F4 -> 14961.598 | E12: ='Balance Sheet'!G4 -> 18878.983 | F12: ='Balance Sheet'!H4 -> 25679.887 | G12: ='Balance Sheet'!I4 -> 34245.046
A14: Scenario comparison, FY2030E | C14: Base | D14: Upside | E14: Downside
A15: Revenue ($M) | C15: =Scenarios!C22 -> 85725.063 | D15: =Scenarios!D22 -> 95429.787 | E15: =Scenarios!E22 -> 68054.857
A16: Net income attributable to Intel ($M) | C16: =Scenarios!C23 -> 8105.147 | D16: =Scenarios!D23 -> 13183.476 | E16: =Scenarios!E23 -> 4038.8517
A17: EPS, diluted ($) | C17: =Scenarios!C24 -> 1.5518895 | D17: =Scenarios!D24 -> 2.5242353 | E17: =Scenarios!E24 -> 0.77331746
A18: Ending cash ($M) | C18: =Scenarios!C25 -> 34692.046 | D18: =Scenarios!D25 -> 53809.717 | E18: =Scenarios!E25 -> 23929.384
A19: Debt / EBITDA | C19: =Scenarios!C26 -> 1.7458019 | D19: =Scenarios!D26 -> 1.3937563 | E19: =Scenarios!E26 -> 2.2502593
A20: DCF value per share ($) | C20: =Scenarios!C27 -> 5.2732343 | D20: =Scenarios!D27 -> 12.199706 | E20: =Scenarios!E27 -> 1.9665087
A23: Valuation per share
A24: ='Valuation Summary'!A4 -> DCF (WACC 15.3%, terminal growth 3.0%) | B24: ='Valuation Summary'!B4 -> 5.2732343 | C24: ='Valuation Summary'!C4 -> Base Case
A25: ='Valuation Summary'!A5 -> Comps: EV / EBITDA (peer median) | B25: ='Valuation Summary'!B5 -> 49.679289 | C25: ='Valuation Summary'!C5 -> Trailing
A26: ='Valuation Summary'!A6 -> Comps: EV / Revenue (peer median) | B26: ='Valuation Summary'!B6 -> 163.35206 | C26: ='Valuation Summary'!C6 -> Trailing
A27: ='Valuation Summary'!A7 -> Current share price | B27: ='Valuation Summary'!B7 -> 91.69 | C27: ='Valuation Summary'!C7 -> Market, Oct 21 2026
A28: ='Valuation Summary'!A8 -> DCF at 9.3% WACC (low discount rate) | B28: ='Valuation Summary'!B8 -> 14.479721 | C28: ='Valuation Summary'!C8 -> 9.3% WACC, 3.0% terminal growth

Sheet Assumptions
A1: Years | B1: FY2023 | C1: FY2024 | D1: FY2025 | E1: FY2026E | F1: FY2027E | G1: FY2028E | H1: FY2029E | I1: FY2030E | K1: Notes
A2: Growth | J2: ="Case: "&Scenarios!$B$2 -> Case: Base
A3: Revenue growth % | C3: ='Income Statement'!C2/'Income Statement'!B2-1 -> -0.020782622 | D3: ='Income Statement'!D2/'Income Statement'!C2-1 -> -0.0046703452 | E3: =CHOOSE(Scenarios!$B$1,Scenarios!E5,Scenarios!E6,Scenarios!E7)+Sensitivity!$B$3 -> 0.15 | F3: =CHOOSE(Scenarios!$B$1,Scenarios!F5,Scenarios!F6,Scenarios!F7)+Sensitivity!$B$3 -> 0.12 | G3: =CHOOSE(Scenarios!$B$1,Scenarios!G5,Scenarios!G6,Scenarios!G7)+Sensitivity!$B$3 -> 0.1 | H3: =CHOOSE(Scenarios!$B$1,Scenarios!H5,Scenarios!H6,Scenarios!H7)+Sensitivity!$B$3 -> 0.08 | I3: =CHOOSE(Scenarios!$B$1,Scenarios!I5,Scenarios!I6,Scenarios!I7)+Sensitivity!$B$3 -> 0.06 | K3: FY2026 growth of 15%: Q2 2026 revenue was $16.1B (+25% YoY) and Q3 guidance is $15.8 to 16.8B. Intel gave no full-year guidance, so I use a rate below the current quarterly run rate to stay conservative. Source: Intel Q2 2026 earnings release | L3: Growth fades from 15% in FY2026 to 6% in FY2030 as the recovery matures.
A4: Margins
A5: Gross margin % | B5: ='Income Statement'!B4/'Income Statement'!B2+Sensitivity!$B$3 -> 0.40036513 | C5: ='Income Statement'!C4/'Income Statement'!C2+Sensitivity!$B$3 -> 0.32664168 | D5: ='Income Statement'!D4/'Income Statement'!D2+Sensitivity!$B$3 -> 0.34766238 | E5: =CHOOSE(Scenarios!$B$1,Scenarios!E10,Scenarios!E11,Scenarios!E12) -> 0.35 | F5: =CHOOSE(Scenarios!$B$1,Scenarios!F10,Scenarios!F11,Scenarios!F12)+Sensitivity!$B$4 -> 0.36 | G5: =CHOOSE(Scenarios!$B$1,Scenarios!G10,Scenarios!G11,Scenarios!G12)+Sensitivity!$B$4 -> 0.37 | H5: =CHOOSE(Scenarios!$B$1,Scenarios!H10,Scenarios!H11,Scenarios!H12)+Sensitivity!$B$4 -> 0.38 | I5: =CHOOSE(Scenarios!$B$1,Scenarios!I10,Scenarios!I11,Scenarios!I12)+Sensitivity!$B$4 -> 0.38 | K5: Gross margin held near the FY2025 level (34.8%), after a drop from 40.0% in FY2023. No evidence yet of a sustained recovery, so I assume stability.
A6: R&D % of revenue | B6: ='Income Statement'!B5/'Income Statement'!B2 -> 0.2958988 | C6: ='Income Statement'!C5/'Income Statement'!C2 -> 0.31159489 | D6: ='Income Statement'!D5/'Income Statement'!D2 -> 0.26060962 | E6: 0.24 | F6: 0.22 | G6: 0.2 | H6: 0.19 | I6: 0.18 | K6: R&D at 24% of revenue, continuing the decline from 26.1% in FY2025 as revenue grows faster than spending.
A7: MG&A % of revenue | B7: ='Income Statement'!B6/'Income Statement'!B2 -> 0.10389467 | C7: ='Income Statement'!C6/'Income Statement'!C2 -> 0.10370803 | D7: ='Income Statement'!D6/'Income Statement'!D2 -> 0.087487938 | E7: 0.09 | F7: 0.085 | G7: 0.08 | H7: 0.08 | I7: 0.08 | K7: MG&A at 9% of revenue, roughly flat vs. FY2025 (8.7%) and below FY2023 and FY2024 (10.4%).
A8: Taxes
A9: Effective tax rate | B9: ='Income Statement'!B13/'Income Statement'!B12 -> -1.1981627 | C9: ='Income Statement'!C13/'Income Statement'!C12 -> -0.71570027 | D9: ='Income Statement'!D13/'Income Statement'!D12 -> 0.98330122 | E9: 0.21 | F9: 0.21 | G9: 0.21 | H9: 0.21 | I9: 0.21 | K9: Historical rates distorted by one-time items (see Notes tab). Using the 21% US statutory rate.
A10: Other
A11: Restricted Cash | D11: 447 | E11: 447 | F11: 447 | G11: 447 | H11: 447 | I11: 447 | K11: Restricted cash held constant at 447. Included in other long-term assets; excluded from balance sheet cash (10-K Note 6).
A12: Restructuring and other charges ($M) | E12: 3000 | F12: 1500 | G12: 1000 | H12: 500 | I12: 500 | K12: Sized so total operating expenses (R&D + MG&A + restructuring) are about $23.0B, in line with Intel's FY2026 GAAP operating expense estimate (Q2 2026 earnings release).
A13: Gains (losses) on equity investments, net ($M) | E13: 0 | F13: 0 | G13: 0 | H13: 0 | I13: 0 | K13: Assumed zero: investment gains are unpredictable and not part of core operations.
A14: Other non-operating income, net ($M) | E14: 0 | F14: 0 | G14: 0 | H14: 0 | I14: 0 | K14: Assumed 250, about the FY2024 level. FY2025 (3,257) was inflated by one-time items such as a 5,323 gain on divestitures and a 1,796 loss on escrow shares.
A15: Net income attributable to non-controlling interests ($M) | E15: 293 | F15: 293 | G15: 293 | H15: 293 | I15: 293 | K15: Held flat at the FY2025 level (293), since outside investors' stakes in Intel subsidiaries are not expected to change materially.
A16: Weighted average shares, basic (millions) | E16: ='Share Count'!E9 -> 5018.97 | F16: ='Share Count'!F9 -> 5069.1597 | G16: ='Share Count'!G9 -> 5119.8513 | H16: ='Share Count'!H9 -> 5171.0498 | I16: ='Share Count'!I9 -> 5222.7603 | K16: 4,994M shares outstanding at the end of FY2025 per the balance sheet, up from 4,330M; the FY2026 average should be at least this level.
A17: Weighted average shares, diluted (millions) | E17: ='Share Count'!E9 -> 5018.97 | F17: ='Share Count'!F9 -> 5069.1597 | G17: ='Share Count'!G9 -> 5119.8513 | H17: ='Share Count'!H9 -> 5171.0498 | I17: ='Share Count'!I9 -> 5222.7603 | K17: Same as basic, since diluted equals basic when there is a net loss.
A20: Working capital
A21: Days sales outstanding (DSO) | B21: ='Balance Sheet'!B6/'Income Statement'!B2*365 -> 22.898318 | C21: ='Balance Sheet'!C6/'Income Statement'!C2*365 -> 23.906706 | D21: ='Balance Sheet'!D6/'Income Statement'!D2*365 -> 26.511929 | E21: 28 | F21: 28 | G21: 28 | H21: 28 | I21: 28 | K21: DSO of 28 days: collection time has lengthened each year (22.9, 23.9, 26.5), so I assume the trend continues slightly.
A22: Days inventory outstanding (DIO) | B22: ='Balance Sheet'!B7/'Income Statement'!B3*365 -> 124.89944 | C22: ='Balance Sheet'!C7/'Income Statement'!C3*365 -> 124.51812 | D22: ='Balance Sheet'!D7/'Income Statement'!D3*365 -> 122.9935 | E22: 121 | F22: 121 | G22: 121 | H22: 121 | I22: 121 | K22: DIO of 121 days: inventory days have been stable at 123 to 125, so I assume a small improvement as production scales with higher revenue.
A23: Days payable outstanding (DPO) | B23: ='Balance Sheet'!B20/'Income Statement'!B3*365 -> 96.287173 | C23: ='Balance Sheet'!C20/'Income Statement'!C3*365 -> 128.17261 | D23: ='Balance Sheet'!D20/'Income Statement'!D3*365 -> 104.61541 | E23: 112 | F23: 112 | G23: 112 | H23: 112 | I23: 112 | K23: DPO of 112 days: between FY2025 (104.6) and the three-year average (about 110). FY2024 (128.2) looks like an outlier, so I don't carry it forward. Assumes Intel pays suppliers slightly slower than in FY2025.
A25: Fixed Assets
A26: Capex % of revenue | B26: =-'Cash Flow Statement'!B25/'Income Statement'!B2 -> 0.47484694 | C26: =-'Cash Flow Statement'!C25/'Income Statement'!C2 -> 0.4509143 | D26: =-'Cash Flow Statement'!D25/'Income Statement'!D2 -> 0.27710821 | E26: =CHOOSE(Scenarios!$B$1,Scenarios!E15,Scenarios!E16,Scenarios!E17) -> 0.2 | F26: =CHOOSE(Scenarios!$B$1, Scenarios!F15, Scenarios!F16, Scenarios!F17) -> 0.2 | G26: =CHOOSE(Scenarios!$B$1, Scenarios!G15, Scenarios!G16, Scenarios!G17) -> 0.18 | H26: =CHOOSE(Scenarios!$B$1, Scenarios!H15, Scenarios!H16, Scenarios!H17) -> 0.16 | I26: =CHOOSE(Scenarios!$B$1, Scenarios!I15, Scenarios!I16, Scenarios!I17) -> 0.15 | K26: Capex at 20% of revenue (about $12.2B), below FY2025's 27.7% but above the Q2 2026 pace of $2.65B per quarter; CFO says investment in equipment and clean rooms is increasing. Source: Intel Q2 2026 earnings release.
A27: Depreciation % of beginning PP&E | B27: n/a | C27: ='Cash Flow Statement'!C6/'Balance Sheet'!B11 -> 0.10296233 | D27: ='Cash Flow Statement'!D6/'Balance Sheet'!C11 -> 0.099676609 | E27: 0.11 | F27: 0.11 | G27: 0.11 | H27: 0.11 | I27: 0.11 | K27: Depreciation at 11% of beginning PP&E (about $11.6B), up from 10.3% and 10.0% in FY2024 and FY2025 to match Intel's pace: first-half 2026 depreciation was $5.9B, about $11.8B annualized. Source: Intel Q2 2026 earnings release.
A28: Amortization of Intangibles ($M) | B28: 1755 | C28: 1428 | D28: 949 | E28: 800 | F28: 700 | G28: 500 | H28: 400 | I28: 300
A29: Share-based compensation ($M) | B29: 3229 | C29: 3410 | D29: 2434 | E29: 2400 | F29: 2400 | G29: 2400 | H29: 2400 | I29: 2400 | K29: Forecast extended to FY2030E. Growth fades from 15% to 6%, margins improve gradually, restructuring winds down, and capex normalizes (see column K on the Assumptions tab).
A31: Debt
A32: Scheduled debt maturities ($M, 10-K Note 13) | E32: 2500 | F32: 3826 | G32: 3173 | H32: 3288 | I32: 2750 | K32: Scheduled maturities from the 10-K debt table; FY2031 is my estimate
A33: % of maturities refinanced with new debt | E33: 0.5 | F33: 0.5 | G33: 0.5 | H33: 0.5 | I33: 0.5 | K33: Share of maturities refinanced with new debt (my assumption)
A34: Interest rate on cash and short-term investments | E34: 0.0375 | F34: 0.0375 | G34: 0.0375 | H34: 0.0375 | I34: 0.0375 | K34: Applied to beginning-of-year cash and short-term investments to avoid circularity
A35: Interest expense rate on average debt (net of capitalized interest) | E35: 0.025 | F35: 0.025 | G35: 0.025 | H35: 0.025 | I35: 0.025 | K35: Net of capitalized interest; Intel's FY2025 figure was about 2.3% of average debt
A38: All model checks | E38: =Checks!B14 -> ALL CHECKS PASS

Sheet Income Statement
A1: Years ended ( In Millions, Except Per Share Amounts) | B1: FY2023 | C1: FY2024 | D1: FY2025 | E1: FY2026E | F1: FY2027E | G1: FY2028E | H1: FY2029E | I1: FY2030E | J1: Income Statement 10-K Page 60
A2: Net Revenue | B2: 54228 | C2: 53101 | D2: 52853 | E2: =D2*(1+Assumptions!E3) -> 60780.95 | F2: =E2*(1+Assumptions!F3) -> 68074.664 | G2: =F2*(1+Assumptions!G3) -> 74882.13 | H2: =G2*(1+Assumptions!H3) -> 80872.701 | I2: =H2*(1+Assumptions!I3) -> 85725.063 | J2: ="Case: "&Scenarios!$B$2 -> Case: Base
A3: Cost of Sales | B3: 32517 | C3: 35756 | D3: 34478 | E3: =E2*(1-Assumptions!E5) -> 39507.618 | F3: =F2*(1-Assumptions!F5) -> 43567.785 | G3: =G2*(1-Assumptions!G5) -> 47175.742 | H3: =H2*(1-Assumptions!H5) -> 50141.075 | I3: =I2*(1-Assumptions!I5) -> 53149.539
A4: Gross Profit | B4: =(B2-B3) -> 21711 | C4: =(C2-C3) -> 17345 | D4: =(D2-D3) -> 18375 | E4: =(E2-E3) -> 21273.332 | F4: =(F2-F3) -> 24506.879 | G4: =(G2-G3) -> 27706.388 | H4: =(H2-H3) -> 30731.626 | I4: =(I2-I3) -> 32575.524
A5: Research and development | B5: 16046 | C5: 16546 | D5: 13774 | E5: =E2*Assumptions!E6 -> 14587.428 | F5: =F2*Assumptions!F6 -> 14976.426 | G5: =G2*Assumptions!G6 -> 14976.426 | H5: =H2*Assumptions!H6 -> 15365.813 | I5: =I2*Assumptions!I6 -> 15430.511
A6: Marketing, general, and administrative | B6: 5634 | C6: 5507 | D6: 4624 | E6: =E2*Assumptions!E7 -> 5470.2855 | F6: =F2*Assumptions!F7 -> 5786.3464 | G6: =G2*Assumptions!G7 -> 5990.5704 | H6: =H2*Assumptions!H7 -> 6469.8161 | I6: =I2*Assumptions!I7 -> 6858.005
A7: Restructuring and other charges | B7: -62 | C7: 6970 | D7: 2191 | E7: =Assumptions!E12 -> 3000 | F7: =Assumptions!F12 -> 1500 | G7: =Assumptions!G12 -> 1000 | H7: =Assumptions!H12 -> 500 | I7: =Assumptions!I12 -> 500
A8: Operating expenses | B8: =SUM(B5:B7) -> 21618 | C8: =SUM(C5:C7) -> 29023 | D8: =SUM(D5:D7) -> 20589 | E8: =SUM(E5:E7) -> 23057.713 | F8: =SUM(F5:F7) -> 22262.773 | G8: =SUM(G5:G7) -> 21966.997 | H8: =SUM(H5:H7) -> 22335.629 | I8: =SUM(I5:I7) -> 22788.516
A9: Operating income (loss) | B9: =B4-B8 -> 93 | C9: =C4-C8 -> -11678 | D9: =D4-D8 -> -2214 | E9: =E4-E8 -> -1784.381 | F9: =F4-F8 -> 2244.1065 | G9: =G4-G8 -> 5739.3917 | H9: =H4-H8 -> 8395.9971 | I9: =I4-I8 -> 9787.0075
A10: Gains (losses) on equity investments, net | B10: 40 | C10: 242 | D10: 514 | E10: =Assumptions!E13 -> 0 | F10: =Assumptions!F13 -> 0 | G10: =Assumptions!G13 -> 0 | H10: =Assumptions!H13 -> 0 | I10: =Assumptions!I13 -> 0
A11: Interest and other, net | B11: 629 | C11: 226 | D11: 3257 | E11: ='Debt Schedule'!E20+Assumptions!E14 -> 254.1 | F11: ='Debt Schedule'!F20+Assumptions!F14 -> 298.08573 | G11: ='Debt Schedule'!G20+Assumptions!G14 -> 363.50369 | H11: ='Debt Schedule'!H20+Assumptions!H14 -> 550.78687 | I11: ='Debt Schedule'!I20+Assumptions!I14 -> 843.55828
A12: Income (loss) before taxes | B12: =SUM(B9:B11) -> 762 | C12: =SUM(C9:C11) -> -11210 | D12: =SUM(D9:D11) -> 1557 | E12: =SUM(E9:E11) -> -1530.281 | F12: =SUM(F9:F11) -> 2542.1922 | G12: =SUM(G9:G11) -> 6102.8954 | H12: =SUM(H9:H11) -> 8946.784 | I12: =SUM(I9:I11) -> 10630.566
A13: Provision for (benefit from) taxes | B13: -913 | C13: 8023 | D13: 1531 | E13: =E12*Assumptions!E9 -> -321.35901 | F13: =F12*Assumptions!F9 -> 533.86037 | G13: =G12*Assumptions!G9 -> 1281.608 | H13: =H12*Assumptions!H9 -> 1878.8246 | I13: =I12*Assumptions!I9 -> 2232.4188
A14: Net income (loss) | B14: =SUM(B12-B13) -> 1675 | C14: =SUM(C12-C13) -> -19233 | D14: =SUM(D12-D13) -> 26 | E14: =SUM(E12-E13) -> -1208.922 | F14: =SUM(F12-F13) -> 2008.3319 | G14: =SUM(G12-G13) -> 4821.2874 | H14: =SUM(H12-H13) -> 7067.9593 | I14: =SUM(I12-I13) -> 8398.147
A15: Less: net income attributable to non-controlling interests | B15: -14 | C15: -477 | D15: 293 | E15: =Assumptions!E15 -> 293 | F15: =Assumptions!F15 -> 293 | G15: =Assumptions!G15 -> 293 | H15: =Assumptions!H15 -> 293 | I15: =Assumptions!I15 -> 293
A16: Net income (loss) attributable to Intel | B16: =(B14-B15) -> 1689 | C16: =(C14-C15) -> -18756 | D16: =(D14-D15) -> -267 | E16: =(E14-E15) -> -1501.922 | F16: =(F14-F15) -> 1715.3319 | G16: =(G14-G15) -> 4528.2874 | H16: =(H14-H15) -> 6774.9593 | I16: =(I14-I15) -> 8105.147
A17: Earnings (loss) per share attributable to Intel - basic | B17: 0.4 | C17: -4.38 | D17: -0.06 | E17: =E16/E20 -> -0.29924905 | F17: =F16/F20 -> 0.33838584 | G17: =G16/G20 -> 0.88445682 | H17: =H16/H20 -> 1.310171 | I17: =I16/I20 -> 1.5518895
A18: Earnings (loss) per share attributable to Intel - diluted | B18: 0.4 | C18: -4.38 | D18: -0.06 | E18: =E16/E21 -> -0.29924905 | F18: =F16/F21 -> 0.33838584 | G18: =G16/G21 -> 0.88445682 | H18: =H16/H21 -> 1.310171 | I18: =I16/I21 -> 1.5518895
A19: Weighted average shares of common stock outstanding:
A20: Basic | B20: 4190 | C20: 4280 | D20: 4530 | E20: =Assumptions!E16 -> 5018.97 | F20: =Assumptions!F16 -> 5069.1597 | G20: =Assumptions!G16 -> 5119.8513 | H20: =Assumptions!H16 -> 5171.0498 | I20: =Assumptions!I16 -> 5222.7603
A21: Diluted | B21: 4212 | C21: 4280 | D21: 4530 | E21: =Assumptions!E17 -> 5018.97 | F21: =Assumptions!F17 -> 5069.1597 | G21: =Assumptions!G17 -> 5119.8513 | H21: =Assumptions!H17 -> 5171.0498 | I21: =Assumptions!I17 -> 5222.7603
A24: Reported per 10-K | E24: Snapshot of earlier version
A25: Operating expenses | B25: 21618 | C25: 29023 | D25: 20589 | E25: 23058
A26: Operating income | B26: 93 | C26: -11678 | D26: -2214 | E26: -1784
A27: Income before taxes | B27: 762 | C27: -11210 | D27: 1557 | E27: -1530
A28: Net income | B28: 1675 | C28: -19233 | D28: 26 | E28: -1209
A29: Net income attributable to Intel | B29: 1689 | C29: -18756 | D29: -267 | E29: -1502
A30: Check (calculated minus reported)
A31: Operating Expenses Check | B31: =B8-B25 -> 0 | C31: =C8-C25 -> 0 | D31: =D8-D25 -> 0 | E31: =E8-E25 -> -0.2865
A32: Operating Income Check | B32: =B9-B26 -> 0 | C32: =C9-C26 -> 0 | D32: =D9-D26 -> 0 | E32: =E9-E26 -> -0.381
A33: Income before taxes Check | B33: =B12-B27 -> 0 | C33: =C12-C27 -> 0 | D33: =D12-D27 -> 0 | E33: =E12-E27 -> -0.281
A34: Net Income Check | B34: =B14-B28 -> 0 | C34: =C14-C28 -> 0 | D34: =D14-D28 -> 0 | E34: =E14-E28 -> 0.07801
A35: Net income attributable to Intel Check | B35: =B16-B29 -> 0 | C35: =C16-C29 -> 0 | D35: =D16-D29 -> 0 | E35: =E16-E29 -> 0.07801

Sheet Balance Sheet
A1: (In Millions, Except Par Value) | B1: FY2023 | C1: FY2024 | D1: FY2025 | E1: FY2026E | F1: FY2027E | G1: FY2028E | H1: FY2029E | I1: FY2030E | J1: Balance Sheet FY2024 10-K p.59 (FY2023, FY2024); FY2025 10-K p.62 (FY2024, FY2025).
A2: Assets | J2: ="Case: "&Scenarios!$B$2 -> Case: Base
A3: Current assets:
A4: Cash and cash equivalents | B4: 7079 | C4: 8249 | D4: 14265 | E4: ='Cash Flow Statement'!E48-Assumptions!E11 -> 14383.619 | F4: ='Cash Flow Statement'!F48-Assumptions!F11 -> 14961.598 | G4: ='Cash Flow Statement'!G48-Assumptions!G11 -> 18878.983 | H4: ='Cash Flow Statement'!H48-Assumptions!H11 -> 25679.887 | I4: ='Cash Flow Statement'!I48-Assumptions!I11 -> 34245.046
A5: Short-term investments | B5: 17955 | C5: 13813 | D5: 23151 | E5: =D5 -> 23151 | F5: =E5 -> 23151 | G5: =F5 -> 23151 | H5: =G5 -> 23151 | I5: =H5 -> 23151
A6: Accounts receivables, net | B6: 3402 | C6: 3478 | D6: 3839 | E6: =Assumptions!E21/365*'Income Statement'!E2 -> 4662.6482 | F6: =Assumptions!F21/365*'Income Statement'!F2 -> 5222.166 | G6: =Assumptions!G21/365*'Income Statement'!G2 -> 5744.3826 | H6: =Assumptions!H21/365*'Income Statement'!H2 -> 6203.9332 | I6: =Assumptions!I21/365*'Income Statement'!I2 -> 6576.1692
A7: Inventories | B7: 11127 | C7: 12198 | D7: 11618 | E7: =Assumptions!E22/365*'Income Statement'!E3 -> 13097.046 | F7: =Assumptions!F22/365*'Income Statement'!F3 -> 14443.019 | G7: =Assumptions!G22/365*'Income Statement'!G3 -> 15639.082 | H7: =Assumptions!H22/365*'Income Statement'!H3 -> 16622.11 | I7: =Assumptions!I22/365*'Income Statement'!I3 -> 17619.436
A8: Other current assets | B8: 3706 | C8: 9586 | D8: 10815 | E8: =D8 -> 10815 | F8: =E8 -> 10815 | G8: =F8 -> 10815 | H8: =G8 -> 10815 | I8: =H8 -> 10815
A9: Total current assets | B9: =SUM(B4:B8) -> 43269 | C9: =SUM(C4:C8) -> 47324 | D9: =SUM(D4:D8) -> 63688 | E9: =SUM(E4:E8) -> 66109.313 | F9: =SUM(F4:F8) -> 68592.784 | G9: =SUM(G4:G8) -> 74228.448 | H9: =SUM(H4:H8) -> 82471.93 | I9: =SUM(I4:I8) -> 92406.651
A11: Property, plant and equipment, net | B11: 96647 | C11: 107919 | D11: 105414 | E11: =D11-'Cash Flow Statement'!E25-'Cash Flow Statement'!E6 -> 105974.65 | F11: =E11-'Cash Flow Statement'!F25-'Cash Flow Statement'!F6 -> 107932.37 | G11: =F11-'Cash Flow Statement'!G25-'Cash Flow Statement'!G6 -> 109538.59 | H11: =G11-'Cash Flow Statement'!H25-'Cash Flow Statement'!H6 -> 110428.98 | I11: =H11-'Cash Flow Statement'!I25-'Cash Flow Statement'!I6 -> 111140.55
A12: Equity investments | B12: 5829 | C12: 5383 | D12: 8512 | E12: =D12 -> 8512 | F12: =E12 -> 8512 | G12: =F12 -> 8512 | H12: =G12 -> 8512 | I12: =H12 -> 8512
A13: Goodwill | B13: 27591 | C13: 24693 | D13: 23912 | E13: =D13 -> 23912 | F13: =E13 -> 23912 | G13: =F13 -> 23912 | H13: =G13 -> 23912 | I13: =H13 -> 23912
A14: Identified intangible assets, net | B14: 4589 | C14: 3691 | D14: 2772 | E14: =D14-Assumptions!E28 -> 1972 | F14: =E14-Assumptions!F28 -> 1272 | G14: =F14-Assumptions!G28 -> 772 | H14: =G14-Assumptions!H28 -> 372 | I14: =H14-Assumptions!I28 -> 72
A15: Other long-term assets | B15: 13647 | C15: 7475 | D15: 7131 | E15: =D15 -> 7131 | F15: =E15 -> 7131 | G15: =F15 -> 7131 | H15: =G15 -> 7131 | I15: =H15 -> 7131
A16: Total assets | B16: =SUM(B9:B15) -> 191572 | C16: =SUM(C9:C15) -> 196485 | D16: =SUM(D9:D15) -> 211429 | E16: =SUM(E9:E15) -> 213610.96 | F16: =SUM(F9:F15) -> 217352.15 | G16: =SUM(G9:G15) -> 224094.04 | H16: =SUM(H9:H15) -> 232827.91 | I16: =SUM(I9:I15) -> 243174.2
A18: Liabilities and stockholders' equity
A19: Current liabilities:
A20: Accounts payable | B20: 8578 | C20: 12556 | D20: 9882 | E20: =Assumptions!E23/365*'Income Statement'!E3 -> 12122.885 | F20: =Assumptions!F23/365*'Income Statement'!F3 -> 13368.745 | G20: =Assumptions!G23/365*'Income Statement'!G3 -> 14475.844 | H20: =Assumptions!H23/365*'Income Statement'!H3 -> 15385.754 | I20: =Assumptions!I23/365*'Income Statement'!I3 -> 16308.9
A21: Accrued compensation and benefits | B21: 3655 | C21: 3343 | D21: 3990 | E21: =D21 -> 3990 | F21: =E21 -> 3990 | G21: =F21 -> 3990 | H21: =G21 -> 3990 | I21: =H21 -> 3990
A22: Short-term debt | B22: 2288 | C22: 3729 | D22: 2499 | E22: ='Debt Schedule'!E12 -> 3826 | F22: ='Debt Schedule'!F12 -> 3173 | G22: ='Debt Schedule'!G12 -> 3288 | H22: ='Debt Schedule'!H12 -> 2750 | I22: ='Debt Schedule'!I12 -> 1750
A23: Income taxes payable | B23: 1107 | C23: 1756 | D23: 604 | E23: =D23 -> 604 | F23: =E23 -> 604 | G23: =F23 -> 604 | H23: =G23 -> 604 | I23: =H23 -> 604
A24: Other accrued liabilities | B24: 12425 | C24: 14282 | D24: 14600 | E24: =D24 -> 14600 | F24: =E24 -> 14600 | G24: =F24 -> 14600 | H24: =G24 -> 14600 | I24: =H24 -> 14600
A25: Total current liabilities | B25: =SUM(B20:B24) -> 28053 | C25: =SUM(C20:C24) -> 35666 | D25: =SUM(D20:D24) -> 31575 | E25: =SUM(E20:E24) -> 35142.885 | F25: =SUM(F20:F24) -> 35735.745 | G25: =SUM(G20:G24) -> 36957.844 | H25: =SUM(H20:H24) -> 37329.754 | I25: =SUM(I20:I24) -> 37252.9
A27: Debt | B27: 46978 | C27: 46282 | D27: 44086 | E27: ='Debt Schedule'!E13 -> 41509 | F27: ='Debt Schedule'!F13 -> 40249 | G27: ='Debt Schedule'!G13 -> 38547.5 | H27: ='Debt Schedule'!H13 -> 37441.5 | I27: ='Debt Schedule'!I13 -> 37066.5
A28: Other long-term liabilities | B28: 6576 | C28: 9505 | D28: 9408 | E28: =D28 -> 9408 | F28: =E28 -> 9408 | G28: =F28 -> 9408 | H28: =G28 -> 9408 | I28: =H28 -> 9408
A29: Commitments and Contingencies (Note 19)
A30: Stockholders' equity:
A31: Preferred stock, $0.001 par value, 50 shares authorized: none issued | B31: 0 | C31: 0 | D31: 0 | E31: =D31 -> 0 | F31: =E31 -> 0 | G31: =F31 -> 0 | H31: =G31 -> 0 | I31: =H31 -> 0
A32: Common stock, $0.001 par value, 10,000 shares authorized: 4,994 shares issued and outstanding (4,330 issued and outstanding in 2024) and capital in excess of par value | B32: 36649 | C32: 50949 | D32: 65185 | E32: =D32+Assumptions!E29 -> 67585 | F32: =E32+Assumptions!F29 -> 69985 | G32: =F32+Assumptions!G29 -> 72385 | H32: =G32+Assumptions!H29 -> 74785 | I32: =H32+Assumptions!I29 -> 77185
A33: Accumulated other comprehensive income (loss) | B33: -215 | C33: -711 | D33: 113 | E33: =D33 -> 113 | F33: =E33 -> 113 | G33: =F33 -> 113 | H33: =G33 -> 113 | I33: =H33 -> 113
A34: Retained Earnings | B34: 69156 | C34: 49032 | D34: 48983 | E34: =D34+'Income Statement'!E16 -> 47481.078 | F34: =E34+'Income Statement'!F16 -> 49196.41 | G34: =F34+'Income Statement'!G16 -> 53724.697 | H34: =G34+'Income Statement'!H16 -> 60499.657 | I34: =H34+'Income Statement'!I16 -> 68604.804
A35: Total Intel stockholder's equity | B35: =SUM(B31:B34) -> 105590 | C35: =SUM(C31:C34) -> 99270 | D35: =SUM(D31:D34) -> 114281 | E35: =SUM(E31:E34) -> 115179.08 | F35: =SUM(F31:F34) -> 119294.41 | G35: =SUM(G31:G34) -> 126222.7 | H35: =SUM(H31:H34) -> 135397.66 | I35: =SUM(I31:I34) -> 145902.8
A36: Non-controlling interests | B36: 4375 | C36: 5762 | D36: 12079 | E36: =D36+'Income Statement'!E15 -> 12372 | F36: =E36+'Income Statement'!F15 -> 12665 | G36: =F36+'Income Statement'!G15 -> 12958 | H36: =G36+'Income Statement'!H15 -> 13251 | I36: =H36+'Income Statement'!I15 -> 13544
A37: Total stockholder's equity | B37: =SUM(B35:B36) -> 109965 | C37: =SUM(C35:C36) -> 105032 | D37: =SUM(D35:D36) -> 126360 | E37: =SUM(E35:E36) -> 127551.08 | F37: =SUM(F35:F36) -> 131959.41 | G37: =SUM(G35:G36) -> 139180.7 | H37: =SUM(H35:H36) -> 148648.66 | I37: =SUM(I35:I36) -> 159446.8
A38: Calculated total liabilities and equity | B38: =(B25+B27+B28+B37) -> 191572 | C38: =(C25+C27+C28+C37) -> 196485 | D38: =(D25+D27+D28+D37) -> 211429 | E38: =(E25+E27+E28+E37) -> 213610.96 | F38: =(F25+F27+F28+F37) -> 217352.15 | G38: =(G25+G27+G28+G37) -> 224094.04 | H38: =(H25+H27+H28+H37) -> 232827.91 | I38: =(I25+I27+I28+I37) -> 243174.2
A39: Balance sheet balances check | B39: =B16-B38 -> 0 | C39: =C16-C38 -> 0 | D39: =D16-D38 -> 0 | E39: =E16-E38 -> 0 | F39: =F16-F38 -> 0 | G39: =G16-G38 -> 0 | H39: =H16-H38 -> 0 | I39: =I16-I38 -> 0
A41: Balance Check | E41: Snapshot of earlier version
A42: Total Current Assets | B42: 43269 | C42: 47324 | D42: 63688 | E42: 67356
A43: Total Assets | B43: 191572 | C43: 196485 | D43: 211429 | E43: 214858
A44: Total Current Liabilities | B44: 28053 | C44: 35666 | D44: 31575 | E44: 33816
...

Sheet Cash Flow Statement
A1: Years Ended (in Millions) | B1: FY2023 | C1: FY2024 | D1: FY2025 | E1: FY2026E | F1: FY2027E | G1: FY2028E | H1: FY2029E | I1: FY2030E
A2: Cash and cash equivalents, beginning of period | B2: 11144 | C2: 7079 | D2: 8249 | E2: =D48 -> 14712 | F2: =E48 -> 14830.619 | G2: =F48 -> 15408.598 | H2: =G48 -> 19325.983 | I2: =H48 -> 26126.887 | J2: ="Case: "&Scenarios!$B$2 -> Case: Base
A3: Cash flows provided by (used for) operating activities:
A4: Net income (loss) | B4: 1675 | C4: -19233 | D4: 26 | E4: ='Income Statement'!E14 -> -1208.922 | F4: ='Income Statement'!F14 -> 2008.3319 | G4: ='Income Statement'!G14 -> 4821.2874 | H4: ='Income Statement'!H14 -> 7067.9593 | I4: ='Income Statement'!I14 -> 8398.147
A5: Adjustments to reconcile net income (loss) to net cash provided by operating activities:
A6: Depreciation | B6: 7847 | C6: 9951 | D6: 10757 | E6: ='Balance Sheet'!D11*Assumptions!E27 -> 11595.54 | F6: ='Balance Sheet'!E11*Assumptions!F27 -> 11657.211 | G6: ='Balance Sheet'!F11*Assumptions!G27 -> 11872.561 | H6: ='Balance Sheet'!G11*Assumptions!H27 -> 12049.245 | I6: ='Balance Sheet'!H11*Assumptions!I27 -> 12147.188
A7: Share-based compensation | B7: 3229 | C7: 3410 | D7: 2434 | E7: =Assumptions!E29 -> 2400 | F7: =Assumptions!F29 -> 2400 | G7: =Assumptions!G29 -> 2400 | H7: =Assumptions!H29 -> 2400 | I7: =Assumptions!I29 -> 2400
A8: Restructuring and other changes | B8: -424 | C8: 3491 | D8: 476 | E8: 0 | F8: 0 | G8: 0 | H8: 0 | I8: 0
A9: Amortization of intangibles | B9: 1755 | C9: 1428 | D9: 949 | E9: =Assumptions!E28 -> 800 | F9: =Assumptions!F28 -> 700 | G9: =Assumptions!G28 -> 500 | H9: =Assumptions!H28 -> 400 | I9: =Assumptions!I28 -> 300
A10: (Gains) losses on equity investments, net | B10: -42 | C10: -246 | D10: -514 | E10: =-'Income Statement'!E10 -> 0 | F10: =-'Income Statement'!F10 -> 0 | G10: =-'Income Statement'!G10 -> 0 | H10: =-'Income Statement'!H10 -> 0 | I10: =-'Income Statement'!I10 -> 0
A11: Mark-to-market (gains) losses on Escrow Shares | B11: 0 | C11: 0 | D11: 1796 | E11: 0 | F11: 0 | G11: 0 | H11: 0 | I11: 0
A12: (Gains) losses on divestitures | B12: 0 | C12: 0 | D12: -5323 | E12: 0 | F12: 0 | G12: 0 | H12: 0 | I12: 0
A13: Deferred taxes | B13: -2033 | C13: 6132 | D13: 328 | E13: 0 | F13: 0 | G13: 0 | H13: 0 | I13: 0
A14: Impairments and net (gain loss on retirement of property, plant and equipment) | B14: 33 | C14: 2252 | D14: 515 | E14: 0 | F14: 0 | G14: 0 | H14: 0 | I14: 0
A15: Changes in asset and liabilities:
A16: Accounts receivable | B16: 731 | C16: -75 | D16: -449 | E16: =-('Balance Sheet'!E6-'Balance Sheet'!D6) -> -823.64822 | F16: =-('Balance Sheet'!F6-'Balance Sheet'!E6) -> -559.51779 | G16: =-('Balance Sheet'!G6-'Balance Sheet'!F6) -> -522.2166 | H16: =-('Balance Sheet'!H6-'Balance Sheet'!G6) -> -459.55061 | I16: =-('Balance Sheet'!I6-'Balance Sheet'!H6) -> -372.23599
A17: Inventories | B17: 2097 | C17: -1105 | D17: -138 | E17: =-('Balance Sheet'!E7-'Balance Sheet'!D7) -> -1479.0458 | F17: =-('Balance Sheet'!F7-'Balance Sheet'!E7) -> -1345.9733 | G17: =-('Balance Sheet'!G7-'Balance Sheet'!F7) -> -1196.0625 | H17: =-('Balance Sheet'!H7-'Balance Sheet'!G7) -> -983.02799 | I17: =-('Balance Sheet'!I7-'Balance Sheet'!H7) -> -997.32658
A18: Accounts payable | B18: -801 | C18: 634 | D18: 297 | E18: ='Balance Sheet'!E20-'Balance Sheet'!D20 -> 2240.8854 | F18: ='Balance Sheet'!F20-'Balance Sheet'!E20 -> 1245.8596 | G18: ='Balance Sheet'!G20-'Balance Sheet'!F20 -> 1107.0992 | H18: ='Balance Sheet'!H20-'Balance Sheet'!G20 -> 909.9102 | I18: ='Balance Sheet'!I20-'Balance Sheet'!H20 -> 923.14526
A19: Accrued compensation and benefits | B19: -614 | C19: -218 | D19: 788 | E19: 0 | F19: 0 | G19: 0 | H19: 0 | I19: 0
A20: Income taxes | B20: -1498 | C20: -356 | D20: -995 | E20: 0 | F20: 0 | G20: 0 | H20: 0 | I20: 0
A21: Other assets and liabilities | B21: -484 | C21: 2223 | D21: -1250 | E21: 0 | F21: 0 | G21: 0 | H21: 0 | I21: 0
A22: Total adjustments | B22: =SUM(B6:B14)+SUM(B16:B21) -> 9796 | C22: =SUM(C6:C14)+SUM(C16:C21) -> 27521 | D22: =SUM(D6:D14)+SUM(D16:D21) -> 9671 | E22: =SUM(E6:E14)+SUM(E16:E21) -> 14733.731 | F22: =SUM(F6:F14)+SUM(F16:F21) -> 14097.58 | G22: =SUM(G6:G14)+SUM(G16:G21) -> 14161.381 | H22: =SUM(H6:H14)+SUM(H16:H21) -> 14316.577 | I22: =SUM(I6:I14)+SUM(I16:I21) -> 14400.771
A23: Net cash provided by (used for) operating activities | B23: =B4+B22 -> 11471 | C23: =C4+C22 -> 8288 | D23: =D4+D22 -> 9697 | E23: =E4+E22 -> 13524.809 | F23: =F4+F22 -> 16105.912 | G23: =G4+G22 -> 18982.668 | H23: =H4+H22 -> 21384.536 | I23: =I4+I22 -> 22798.918
A24: Cash flows provided by (used for) investing activities:
A25: Additions to property, plant and equipment | B25: -25750 | C25: -23944 | D25: -14646 | E25: =-'Income Statement'!E2*Assumptions!E26 -> -12156.19 | F25: =-'Income Statement'!F2*Assumptions!F26 -> -13614.933 | G25: =-'Income Statement'!G2*Assumptions!G26 -> -13478.783 | H25: =-'Income Statement'!H2*Assumptions!H26 -> -12939.632 | I25: =-'Income Statement'!I2*Assumptions!I26 -> -12858.759
A26: Proceeds from capital-related government incentives | B26: 1011 | C26: 1936 | D26: 1577 | E26: 0 | F26: 0 | G26: 0 | H26: 0 | I26: 0
A27: Purchases of short-term investments | B27: -44414 | C27: -37940 | D27: -24319 | E27: 0 | F27: 0 | G27: 0 | H27: 0 | I27: 0
A28: Maturities and sales of short-term investments | B28: 44077 | C28: 41463 | D28: 15387 | E28: 0 | F28: 0 | G28: 0 | H28: 0 | I28: 0
A29: Sales of equity investments | B29: 472 | C29: 1047 | D29: 671 | E29: 0 | F29: 0 | G29: 0 | H29: 0 | I29: 0
A30: Proceeds from divestitures, net | B30: 0 | C30: 0 | D30: 6157 | E30: 0 | F30: 0 | G30: 0 | H30: 0 | I30: 0
A31: Other investing | B31: 563 | C31: -818 | D31: 352 | E31: 0 | F31: 0 | G31: 0 | H31: 0 | I31: 0
A32: Net cash provided by (used for) investing activities | B32: =SUM(B25:B31) -> -24041 | C32: =SUM(C25:C31) -> -18256 | D32: =SUM(D25:D31) -> -14821 | E32: =SUM(E25:E31) -> -12156.19 | F32: =SUM(F25:F31) -> -13614.933 | G32: =SUM(G25:G31) -> -13478.783 | H32: =SUM(H25:H31) -> -12939.632 | I32: =SUM(I25:I31) -> -12858.759
A33: Cash flows provided by (used for) financing activities:
A34: Issuance of commercial paper, net of issuance costs | B34: 0 | C34: 7349 | D34: 3493 | E34: 0 | F34: 0 | G34: 0 | H34: 0 | I34: 0
A35: Repayment of commercial paper | B35: -3944 | C35: -7349 | D35: -3493 | E35: 0 | F35: 0 | G35: 0 | H35: 0 | I35: 0
A36: Partner contributions | B36: 1511 | C36: 12714 | D36: 5108 | E36: 0 | F36: 0 | G36: 0 | H36: 0 | I36: 0
A37: Net proceeds from sales of subsidiary shares | B37: 2959 | C37: 0 | D37: 921 | E37: 0 | F37: 0 | G37: 0 | H37: 0 | I37: 0
A38: Additions to property, plant and equipment | B38: 0 | C38: -1178 | D38: -3026 | E38: 0 | F38: 0 | G38: 0 | H38: 0 | I38: 0
A39: Issuance of long-term debt, net of issuance costs | B39: 11391 | C39: 2975 | D39: 0 | E39: ='Debt Schedule'!E5 -> 1250 | F39: ='Debt Schedule'!F5 -> 1913 | G39: ='Debt Schedule'!G5 -> 1586.5 | H39: ='Debt Schedule'!H5 -> 1644 | I39: ='Debt Schedule'!I5 -> 1375
A40: Repayment of debt | B40: -423 | C40: -2288 | D40: -3750 | E40: =-'Debt Schedule'!E6 -> -2500 | F40: =-'Debt Schedule'!F6 -> -3826 | G40: =-'Debt Schedule'!G6 -> -3173 | H40: =-'Debt Schedule'!H6 -> -3288 | I40: =-'Debt Schedule'!I6 -> -2750
...

Sheet Scenarios
A1: Scenario Selector (1 = Base,2 = Upside,3 = Downside) | B1: 1
A2: Active Case | B2: =CHOOSE(B1,"Base","Upside","Downside") -> Base | J2: ="Case: "&Scenarios!$B$2 -> Case: Base
E3: =CHOOSE(Scenarios!$B$1,Scenarios!E5,Scenarios!E6,Scenarios!E7) -> 0.15 | F3: =CHOOSE(Scenarios!$B$1,Scenarios!F5,Scenarios!F6,Scenarios!F7) -> 0.12 | G3: =CHOOSE(Scenarios!$B$1,Scenarios!G5,Scenarios!G6,Scenarios!G7) -> 0.1 | H3: =CHOOSE(Scenarios!$B$1,Scenarios!H5,Scenarios!H6,Scenarios!H7) -> 0.08 | I3: =CHOOSE(Scenarios!$B$1,Scenarios!I5,Scenarios!I6,Scenarios!I7) -> 0.06
A4: Revenue growth % | E4: FY2026E | F4: FY2027E | G4: FY2028E | H4: FY2029E | I4: FY2030E
A5: Base | E5: 0.15 | F5: 0.12 | G5: 0.1 | H5: 0.08 | I5: 0.06
A6: Upside | E6: 0.18 | F6: 0.15 | G6: 0.12 | H6: 0.1 | I6: 0.08
A7: Downside | E7: 0.08 | F7: 0.06 | G7: 0.05 | H7: 0.04 | I7: 0.03
A9: Gross Margin % | E9: FY2026E | F9: FY2027E | G9: FY2028E | H9: FY2029E | I9: FY2030E
A10: Base | E10: 0.35 | F10: 0.36 | G10: 0.37 | H10: 0.38 | I10: 0.38
A11: Upside | E11: 0.38 | F11: 0.4 | G11: 0.41 | H11: 0.42 | I11: 0.43
A12: Downside | E12: 0.32 | F12: 0.32 | G12: 0.33 | H12: 0.33 | I12: 0.34
A14: Capex % | E14: FY2026E | F14: FY2027E | G14: FY2028E | H14: FY2029E | I14: FY2030E
A15: Base | E15: 0.2 | F15: 0.2 | G15: 0.18 | H15: 0.16 | I15: 0.15
A16: Upside | E16: 0.18 | F16: 0.17 | G16: 0.16 | H16: 0.14 | I16: 0.12
A17: Downside | E17: 0.23 | F17: 0.22 | G17: 0.2 | H17: 0.18 | I17: 0.17
A20: Scenario comparison, FY2030E | C20: Base | D20: Upside | E20: Downside
C21: 1 | D21: 2 | E21: 3
A22: Revenue ($M) | B22: ='Income Statement'!I2 -> 85725.063 | C22: 85725.063 | D22: 95429.787 | E22: 68054.857
A23: Net income attributable to Intel ($M) | B23: ='Income Statement'!I16 -> 8105.147 | C23: 8105.147 | D23: 13183.476 | E23: 4038.8517
A24: EPS, diluted ($) | B24: ='Income Statement'!I18 -> 1.5518895 | C24: 1.5518895 | D24: 2.5242353 | E24: 0.77331746
A25: Ending cash ($M) | B25: ='Cash Flow Statement'!I48 -> 34692.046 | C25: 34692.046 | D25: 53809.717 | E25: 23929.384
A26: Debt / EBITDA (x) | B26: ='Credit Ratios'!I9 -> 1.7458019 | C26: 1.7458019 | D26: 1.3937563 | E26: 2.2502593
A27: DCF value per share ($) | B27: =DCF!B45 -> 5.2732343 | C27: 5.2732343 | D27: 12.199706 | E27: 1.9665087

Sheet Payback
A1: Payback Analysis
J2: ="Case: "&Scenarios!$B$2 -> Case: Base
E3: FY2026E | F3: FY2027E | G3: FY2028E | H3: FY2029E | I3: FY2030E
A4: Operating cash flows | E4: ='Cash Flow Statement'!E23 -> 13524.809 | F4: ='Cash Flow Statement'!F23 -> 16105.912 | G4: ='Cash Flow Statement'!G23 -> 18982.668 | H4: ='Cash Flow Statement'!H23 -> 21384.536 | I4: ='Cash Flow Statement'!I23 -> 22798.918
A5: Capital expenditures | E5: ='Cash Flow Statement'!E25 -> -12156.19 | F5: ='Cash Flow Statement'!F25 -> -13614.933 | G5: ='Cash Flow Statement'!G25 -> -13478.783 | H5: ='Cash Flow Statement'!H25 -> -12939.632 | I5: ='Cash Flow Statement'!I25 -> -12858.759
A6: Free cash flow | E6: =E4+E5 -> 1368.6194 | F6: =F4+F5 -> 2490.9791 | G6: =G4+G5 -> 5503.8848 | H6: =H4+H5 -> 8444.9041 | I6: =I4+I5 -> 9940.1581
A7: Cumulative free cash flow | E7: =E6 -> 1368.6194 | F7: =F6+E7 -> 3859.5984 | G7: =G6+F7 -> 9363.4833 | H7: =H6+G7 -> 17808.387 | I7: =I6+H7 -> 27748.546
A9: Payback year | B9: {=INDEX(E3:I3,MATCH(TRUE,INDEX(E7:I7>0,0),0))} -> FY2026E | E9: =IF(E7>0,E3,"") -> FY2026E | F9: =IF(F7>0,F3,"") -> FY2027E | G9: =IF(G7>0,G3,"") -> FY2028E | H9: =IF(H7>0,H3,"") -> FY2029E | I9: =IF(I7>0,I3,"") -> FY2030E

Sheet PP&E Schedule
A1: PP&E Schedule ($M)
J2: ="Case: "&Scenarios!$B$2 -> Case: Base
E3: FY2026E | F3: FY2027E | G3: FY2028E | H3: FY2029E | I3: FY2030E
A4: Beginning PP&E | E4: ='Balance Sheet'!D11 -> 105414 | F4: ='Balance Sheet'!E11 -> 105974.65 | G4: ='Balance Sheet'!F11 -> 107932.37 | H4: ='Balance Sheet'!G11 -> 109538.59 | I4: ='Balance Sheet'!H11 -> 110428.98
A5: Plus: capital expenditures | E5: =-'Cash Flow Statement'!E25 -> 12156.19 | F5: =-'Cash Flow Statement'!F25 -> 13614.933 | G5: =-'Cash Flow Statement'!G25 -> 13478.783 | H5: =-'Cash Flow Statement'!H25 -> 12939.632 | I5: =-'Cash Flow Statement'!I25 -> 12858.759
A6: Less: depreciation | E6: ='Cash Flow Statement'!E6 -> 11595.54 | F6: ='Cash Flow Statement'!F6 -> 11657.211 | G6: ='Cash Flow Statement'!G6 -> 11872.561 | H6: ='Cash Flow Statement'!H6 -> 12049.245 | I6: ='Cash Flow Statement'!I6 -> 12147.188
A7: Ending PP&E | E7: =E4+E5-E6 -> 105974.65 | F7: =F4+F5-F6 -> 107932.37 | G7: =G4+G5-G6 -> 109538.59 | H7: =H4+H5-H6 -> 110428.98 | I7: =I4+I5-I6 -> 111140.55
A9: Depreciation % of beginning PP&E | E9: =E6/E4 -> 0.11 | F9: =F6/F4 -> 0.11 | G9: =G6/G4 -> 0.11 | H9: =H6/H4 -> 0.11 | I9: =I6/I4 -> 0.11
A11: PP&E per Balance Sheet | E11: ='Balance Sheet'!E11 -> 105974.65 | F11: ='Balance Sheet'!F11 -> 107932.37 | G11: ='Balance Sheet'!G11 -> 109538.59 | H11: ='Balance Sheet'!H11 -> 110428.98 | I11: ='Balance Sheet'!I11 -> 111140.55
A12: Check (schedule minus Balance Sheet) | E12: =E7-E11 -> 0 | F12: =F7-F11 -> 0 | G12: =G7-G11 -> 0 | H12: =H7-H11 -> 0 | I12: =I7-I11 -> 0

Sheet Working Capital
A1: Working Capital Schedule ($M)
J2: ="Case: "&Scenarios!$B$2 -> Case: Base
D3: FY2025 | E3: FY2026E | F3: FY2027E | G3: FY2028E | H3: FY2029E | I3: FY2030E
A4: Net revenue | D4: ='Income Statement'!D2 -> 52853 | E4: ='Income Statement'!E2 -> 60780.95 | F4: ='Income Statement'!F2 -> 68074.664 | G4: ='Income Statement'!G2 -> 74882.13 | H4: ='Income Statement'!H2 -> 80872.701 | I4: ='Income Statement'!I2 -> 85725.063
A5: Cost of sales | D5: ='Income Statement'!D3 -> 34478 | E5: ='Income Statement'!E3 -> 39507.618 | F5: ='Income Statement'!F3 -> 43567.785 | G5: ='Income Statement'!G3 -> 47175.742 | H5: ='Income Statement'!H3 -> 50141.075 | I5: ='Income Statement'!I3 -> 53149.539
A7: Days sales outstanding (DSO) | D7: =Assumptions!D21 -> 26.511929 | E7: =Assumptions!E21 -> 28 | F7: =Assumptions!F21 -> 28 | G7: =Assumptions!G21 -> 28 | H7: =Assumptions!H21 -> 28 | I7: =Assumptions!I21 -> 28
A8: Days inventory outstanding (DIO) | D8: =Assumptions!D22 -> 122.9935 | E8: =Assumptions!E22 -> 121 | F8: =Assumptions!F22 -> 121 | G8: =Assumptions!G22 -> 121 | H8: =Assumptions!H22 -> 121 | I8: =Assumptions!I22 -> 121
A9: Days payable outstanding (DPO) | D9: =Assumptions!D23 -> 104.61541 | E9: =Assumptions!E23 -> 112 | F9: =Assumptions!F23 -> 112 | G9: =Assumptions!G23 -> 112 | H9: =Assumptions!H23 -> 112 | I9: =Assumptions!I23 -> 112
A11: Accounts receivable | D11: ='Balance Sheet'!D6 -> 3839 | E11: ='Balance Sheet'!E6 -> 4662.6482 | F11: ='Balance Sheet'!F6 -> 5222.166 | G11: ='Balance Sheet'!G6 -> 5744.3826 | H11: ='Balance Sheet'!H6 -> 6203.9332 | I11: ='Balance Sheet'!I6 -> 6576.1692
A12: Inventories | D12: ='Balance Sheet'!D7 -> 11618 | E12: ='Balance Sheet'!E7 -> 13097.046 | F12: ='Balance Sheet'!F7 -> 14443.019 | G12: ='Balance Sheet'!G7 -> 15639.082 | H12: ='Balance Sheet'!H7 -> 16622.11 | I12: ='Balance Sheet'!I7 -> 17619.436
A13: Accounts payable | D13: ='Balance Sheet'!D20 -> 9882 | E13: ='Balance Sheet'!E20 -> 12122.885 | F13: ='Balance Sheet'!F20 -> 13368.745 | G13: ='Balance Sheet'!G20 -> 14475.844 | H13: ='Balance Sheet'!H20 -> 15385.754 | I13: ='Balance Sheet'!I20 -> 16308.9
A14: Net working capital | D14: =D11+D12-D13 -> 5575 | E14: =E11+E12-E13 -> 5636.8087 | F14: =F11+F12-F13 -> 6296.4402 | G14: =G11+G12-G13 -> 6907.6201 | H14: =H11+H12-H13 -> 7440.2885 | I14: =I11+I12-I13 -> 7886.7058
A15: Increase (decrease) in net working capital | E15: =E14-D14 -> 61.808651 | F15: =F14-E14 -> 659.6315 | G15: =G14-F14 -> 611.17993 | H15: =H14-G14 -> 532.66839 | I15: =I14-H14 -> 446.41731
A17: Cash flow impact (per Cash Flow Statement) | E17: ='Cash Flow Statement'!E16+'Cash Flow Statement'!E17+'Cash Flow Statement'!E18 -> -61.808651 | F17: ='Cash Flow Statement'!F16+'Cash Flow Statement'!F17+'Cash Flow Statement'!F18 -> -659.6315 | G17: ='Cash Flow Statement'!G16+'Cash Flow Statement'!G17+'Cash Flow Statement'!G18 -> -611.17993 | H17: ='Cash Flow Statement'!H16+'Cash Flow Statement'!H17+'Cash Flow Statement'!H18 -> -532.66839 | I17: ='Cash Flow Statement'!I16+'Cash Flow Statement'!I17+'Cash Flow Statement'!I18 -> -446.41731
A18: Check (should be 0) | E18: =E15+E17 -> 9.094947e-13 | F18: =F15+F17 -> -1.8189894e-12 | G18: =G15+G17 -> 9.094947e-13 | H18: =H15+H17 -> 0 | I18: =I15+I17 -> -1.8189894e-12

Sheet Debt Schedule
A1: Debt Schedule ($M)
J2: ="Case: "&Scenarios!$B$2 -> Case: Base
D3: FY2025 | E3: FY2026E | F3: FY2027E | G3: FY2028E | H3: FY2029E | I3: FY2030E
A4: Beginning debt | E4: =D7 -> 46585 | F4: =E7 -> 45335 | G4: =F7 -> 43422 | H4: =G7 -> 41835.5 | I4: =H7 -> 40191.5
A5: Plus: new borrowings | E5: =E6*Assumptions!E33 -> 1250 | F5: =F6*Assumptions!F33 -> 1913 | G5: =G6*Assumptions!G33 -> 1586.5 | H5: =H6*Assumptions!H33 -> 1644 | I5: =I6*Assumptions!I33 -> 1375
A6: Less: scheduled repayments | E6: =Assumptions!E32 -> 2500 | F6: =Assumptions!F32 -> 3826 | G6: =Assumptions!G32 -> 3173 | H6: =Assumptions!H32 -> 3288 | I6: =Assumptions!I32 -> 2750
A7: Ending debt | D7: ='Balance Sheet'!D22+'Balance Sheet'!D27 -> 46585 | E7: =E4+E5-E6 -> 45335 | F7: =F4+F5-F6 -> 43422 | G7: =G4+G5-G6 -> 41835.5 | H7: =H4+H5-H6 -> 40191.5 | I7: =I4+I5-I6 -> 38816.5
A9: Total debt per 10-K | D9: 46585
A10: Check (should be 0) | D10: =D7-D9 -> 0
A12: Short-term debt (due next year) | D12: ='Balance Sheet'!D22 -> 2499 | E12: =Assumptions!F32 -> 3826 | F12: =Assumptions!G32 -> 3173 | G12: =Assumptions!H32 -> 3288 | H12: =Assumptions!I32 -> 2750 | I12: 1750
A13: Long-term debt | D13: ='Balance Sheet'!D27 -> 44086 | E13: =E7-E12 -> 41509 | F13: =F7-F12 -> 40249 | G13: =G7-G12 -> 38547.5 | H13: =H7-H12 -> 37441.5 | I13: =I7-I12 -> 37066.5
A14: Check (should be 0) | D14: =D12+D13-D7 -> 0 | E14: =E12+E13-E7 -> 0 | F14: =F12+F13-F7 -> 0 | G14: =G12+G13-G7 -> 0 | H14: =H12+H13-H7 -> 0 | I14: =I12+I13-I7 -> 0
A16: Average debt | E16: =AVERAGE(E4, E7) -> 45960 | F16: =AVERAGE(F4, F7) -> 44378.5 | G16: =AVERAGE(G4, G7) -> 42628.75 | H16: =AVERAGE(H4, H7) -> 41013.5 | I16: =AVERAGE(I4, I7) -> 39504
A17: Interest Expense | E17: =E16*Assumptions!E35 -> 1149 | F17: =F16*Assumptions!F35 -> 1109.4625 | G17: =G16*Assumptions!G35 -> 1065.7188 | H17: =H16*Assumptions!H35 -> 1025.3375 | I17: =I16*Assumptions!I35 -> 987.6
A18: Beginning cash and short-term investments | E18: ='Balance Sheet'!D4+'Balance Sheet'!D5 -> 37416 | F18: ='Balance Sheet'!E4+'Balance Sheet'!E5 -> 37534.619 | G18: ='Balance Sheet'!F4+'Balance Sheet'!F5 -> 38112.598 | H18: ='Balance Sheet'!G4+'Balance Sheet'!G5 -> 42029.983 | I18: ='Balance Sheet'!H4+'Balance Sheet'!H5 -> 48830.887
A19: Interest income | E19: =E18*Assumptions!E34 -> 1403.1 | F19: =F18*Assumptions!F34 -> 1407.5482 | G19: =G18*Assumptions!G34 -> 1429.2224 | H19: =H18*Assumptions!H34 -> 1576.1244 | I19: =I18*Assumptions!I34 -> 1831.1583
A20: Net interest income (expense) | E20: =E19-E17 -> 254.1 | F20: =F19-F17 -> 298.08573 | G20: =G19-G17 -> 363.50369 | H20: =H19-H17 -> 550.78687 | I20: =I19-I17 -> 843.55828

Sheet Credit Ratios
A1: Credit Ratios | D1: FY2025 | E1: FY2026E | F1: FY2027E | G1: FY2028E | H1: FY2029E | I1: FY2030E
A3: EBITDA | E3: ='Income Statement'!E9+'Cash Flow Statement'!E6+'Cash Flow Statement'!E9 -> 10611.159 | F3: ='Income Statement'!F9+'Cash Flow Statement'!F6+'Cash Flow Statement'!F9 -> 14601.318 | G3: ='Income Statement'!G9+'Cash Flow Statement'!G6+'Cash Flow Statement'!G9 -> 18111.953 | H3: ='Income Statement'!H9+'Cash Flow Statement'!H6+'Cash Flow Statement'!H9 -> 20845.242 | I3: ='Income Statement'!I9+'Cash Flow Statement'!I6+'Cash Flow Statement'!I9 -> 22234.195
A4: Total debt | E4: ='Debt Schedule'!E7 -> 45335 | F4: ='Debt Schedule'!F7 -> 43422 | G4: ='Debt Schedule'!G7 -> 41835.5 | H4: ='Debt Schedule'!H7 -> 40191.5 | I4: ='Debt Schedule'!I7 -> 38816.5
A5: Cash and short-term investments | E5: ='Balance Sheet'!E4+'Balance Sheet'!E5 -> 37534.619 | F5: ='Balance Sheet'!F4+'Balance Sheet'!F5 -> 38112.598 | G5: ='Balance Sheet'!G4+'Balance Sheet'!G5 -> 42029.983 | H5: ='Balance Sheet'!H4+'Balance Sheet'!H5 -> 48830.887 | I5: ='Balance Sheet'!I4+'Balance Sheet'!I5 -> 57396.046
A6: Net debt | E6: =E4-E5 -> 7800.3806 | F6: =F4-F5 -> 5309.4016 | G6: =G4-G5 -> -194.48326 | H6: =H4-H5 -> -8639.3874 | I6: =I4-I5 -> -18579.546
A7: Free cash flow | E7: =Payback!E6 -> 1368.6194 | F7: =Payback!F6 -> 2490.9791 | G7: =Payback!G6 -> 5503.8848 | H7: =Payback!H6 -> 8444.9041 | I7: =Payback!I6 -> 9940.1581
A9: Debt / EBITDA (x) | E9: =E4/E3 -> 4.2723891 | F9: =F4/F3 -> 2.9738411 | G9: =G4/G3 -> 2.3098283 | H9: =H4/H3 -> 1.9280898 | I9: =I4/I3 -> 1.7458019
A10: Net debt / EBITDA (x) | E10: =E6/E3 -> 0.73511109 | F10: =F6/F3 -> 0.36362482 | G10: =G6/G3 -> -0.010737841 | H10: =H6/H3 -> -0.41445368 | I10: =I6/I3 -> -0.83562932
A11: Interest coverage (EBITDA / interest expense) (x) | E11: =E3/'Debt Schedule'!E17 -> 9.2351253 | F11: =F3/'Debt Schedule'!F17 -> 13.160713 | G11: =G3/'Debt Schedule'!G17 -> 16.995059 | H11: =H3/'Debt Schedule'!H17 -> 20.330128 | I11: =I3/'Debt Schedule'!I17 -> 22.513361
A12: FCF / debt (%) | E12: =E7/E4 -> 0.030189023 | F12: =F7/F4 -> 0.057366751 | G12: =G7/G4 -> 0.13156015 | H12: =H7/H4 -> 0.21011667 | I12: =I7/I4 -> 0.25608074

Sheet Sensitivity
A1: Sensitivity Analysis
A3: Revenue growth adjustment (+/- percentage points) | B3: 0
A4: Gross margin adjustment (+/- percentage points) | B4: 0
A6: FY2030E net income attributable to Intel ($M): revenue growth vs gross margin adjustment
A8: Revenue growth adjustment across → | B8: ='Income Statement'!I16 -> 8105.147 | C8: =-2% -> -0.02 | D8: -0.01 | E8: 0 | F8: 0.01 | G8: 0.02
A9: Gross Margin adjustment down ↓ | B9: -0.02 | C9: 6106.5999 | D9: 6369.0155 | E9: 6641.7235 | F9: 6925.0167 | G9: 7219.1934
B10: -0.01 | C10: 6776.0962 | D10: 7069.0613 | E10: 7373.4352 | F10: 7689.5415 | G10: 8017.7095
B11: 0 | C11: 7445.5925 | D11: 7769.107 | E11: 8105.147 | F11: 8454.0664 | G11: 8816.2256
B12: 0.01 | C12: 8115.0889 | D12: 8469.1528 | E12: 8836.8588 | F12: 9218.5912 | G12: 9614.7417
B13: 0.02 | C13: 8784.5852 | D13: 9169.1986 | E13: 9568.5705 | F13: 9983.116 | G13: 10413.258
A16: FY2027E Debt / EBITDA (x): revenue growth vs gross margin adjustment
A18: Revenue growth adjustment → | B18: ='Credit Ratios'!F9 -> 2.9738411 | C18: -0.02 | D18: -0.01 | E18: 0 | F18: 0.01 | G18: 0.02
A19: Gross margin adjustment↓ | B19: -0.02 | C19: 3.3062455 | D19: 3.2929406 | E19: 3.2796507 | F19: 3.2663767 | G19: 3.2531195
B20: -0.01 | C20: 3.1487376 | D20: 3.1339876 | E20: 3.1192685 | F20: 3.1045815 | G20: 3.0899275
B21: 0 | C21: 3.0055544 | D21: 2.9896735 | E21: 2.9738411 | F21: 2.9580584 | G21: 2.9423264
B22: 0.01 | C22: 2.8748268 | D22: 2.8580651 | E22: 2.84137 | F22: 2.8247425 | G22: 2.8081838
B23: 0.02 | C23: 2.7549973 | D23: 2.7375552 | E23: 2.7201975 | F23: 2.7029252 | G23: 2.6857391

Sheet DCF
A1: Discounted Cash Flow
E2: FY2026E | F2: FY2027E | G2: FY2028E | H2: FY2029E | I2: FY2030E
A3: Operating Income(EBIT) | E3: ='Income Statement'!E9 -> -1784.381 | F3: ='Income Statement'!F9 -> 2244.1065 | G3: ='Income Statement'!G9 -> 5739.3917 | H3: ='Income Statement'!H9 -> 8395.9971 | I3: ='Income Statement'!I9 -> 9787.0075
A4: Tax rate | E4: =Assumptions!E9 -> 0.21 | F4: =Assumptions!F9 -> 0.21 | G4: =Assumptions!G9 -> 0.21 | H4: =Assumptions!H9 -> 0.21 | I4: =Assumptions!I9 -> 0.21
A5: Tax on EBIT | E5: =-E3*E4 -> 374.72001 | F5: =-F3*F4 -> -471.26237 | G5: =-G3*G4 -> -1205.2723 | H5: =-H3*H4 -> -1763.1594 | I5: =-I3*I4 -> -2055.2716
A6: NOPAT (EBIT after tax) | E6: =E3+E5 -> -1409.661 | F6: =F3+F5 -> 1772.8442 | G6: =G3+G5 -> 4534.1195 | H6: =H3+H5 -> 6632.8377 | I6: =I3+I5 -> 7731.736
A7: Plus: depreciation | E7: ='Cash Flow Statement'!E6 -> 11595.54 | F7: ='Cash Flow Statement'!F6 -> 11657.211 | G7: ='Cash Flow Statement'!G6 -> 11872.561 | H7: ='Cash Flow Statement'!H6 -> 12049.245 | I7: ='Cash Flow Statement'!I6 -> 12147.188
A8: Plus: amortization | E8: ='Cash Flow Statement'!E9 -> 800 | F8: ='Cash Flow Statement'!F9 -> 700 | G8: ='Cash Flow Statement'!G9 -> 500 | H8: ='Cash Flow Statement'!H9 -> 400 | I8: ='Cash Flow Statement'!I9 -> 300
A9: Less: capex | E9: ='Cash Flow Statement'!E25 -> -12156.19 | F9: ='Cash Flow Statement'!F25 -> -13614.933 | G9: ='Cash Flow Statement'!G25 -> -13478.783 | H9: ='Cash Flow Statement'!H25 -> -12939.632 | I9: ='Cash Flow Statement'!I25 -> -12858.759
A10: Less: increase in working capital | E10: ='Working Capital'!E17 -> -61.808651 | F10: ='Working Capital'!F17 -> -659.6315 | G10: ='Working Capital'!G17 -> -611.17993 | H10: ='Working Capital'!H17 -> -532.66839 | I10: ='Working Capital'!I17 -> -446.41731
A11: Unlevered free cash flow | E11: =E6+E7+E8+E9+E10 -> -1232.1196 | F11: =F6+F7+F8+F9+F10 -> -144.50865 | G11: =G6+G7+G8+G9+G10 -> 2816.7169 | H11: =H6+H7+H8+H9+H10 -> 5609.7825 | I11: =I6+I7+I8+I9+I10 -> 6873.7471
A14: Discount Rate (WACC)
A15: Risk-free rate (10-year US Treasury yield) | B15: 0.0513 | C15: 10-year US Treasury yield, FRED series DGS10 (or Yahoo Finance ^TNX), Oct 21 2026
A16: Equity risk premium | B16: 0.05 | C16: Assumption, 5.0%; in line with Damodaran's implied ERP (pages.stern.nyu.edu/~adamodar), Oct 2026
A17: Beta (INTC) | B17: 2.23 | C17: Yahoo Finance, INTC Statistics tab, 5-year monthly beta, Oct 21 2026
A18: Cost of equity | B18: =B15+B17*B16 -> 0.1628
A19: Pre-tax cost of debt | B19: 0.07 | C19: Estimate: 10-year Treasury yield + about 2% credit spread; not a quoted bond yield
A20: Tax rate | B20: =Assumptions!E9 -> 0.21
A21: After-tax cost of debt | B21: =B19*(1-B20) -> 0.0553
A22: Share price | B22: 91.69 | C22: Yahoo Finance, INTC closing price, Oct 21 2026
A23: Shares outstanding (millions) | B23: ='Share Count'!D8 -> 4994
A24: Market value of equity | B24: =B22*B23 -> 457899.86
A25: Total debt | B25: ='Debt Schedule'!D7 -> 46585
A26: Equity weight | B26: =B24/(B24+B25) -> 0.90765828
A27: Debt weight | B27: =B25/(B24+B25) -> 0.092341721
A28: WACC | B28: =B26*B18+B27*B21 -> 0.15287327
A29: WACC adjustment (+/- points) | B29: 0
A30: Valuation
A31: Terminal Growth rate | B31: 0.03
A32: WACC used in valuation | B32: =B28+B29 -> 0.15287327
A33: Discount period (years) | E33: 1 | F33: =E33+1 -> 2 | G33: =F33+1 -> 3 | H33: =G33+1 -> 4 | I33: =H33+1 -> 5
A34: Discount factor | E34: =1/(1+$B$32)^E33 -> 0.86739803 | F34: =1/(1+$B$32)^F33 -> 0.75237934 | G34: =1/(1+$B$32)^G33 -> 0.65261236 | H34: =1/(1+$B$32)^H33 -> 0.56607468 | I34: =1/(1+$B$32)^I33 -> 0.49101206
A35: PV of unlevered free cash flow | E35: =E11*E34 -> -1068.7382 | F35: =F11*F34 -> -108.72533 | G35: =G11*G34 -> 1838.2243 | H35: =H11*H34 -> 3175.5558 | I35: =I11*I34 -> 3375.0927
A37: Sum of PV of FCF, FY2026E to FY2030E | B37: =SUM(E35:I35) -> 7211.4094
A38: Terminal value (at FY2030E) | B38: =I11*(1+B31)/(B32-B31) -> 57620.016
A39: PV of terminal value | B39: =B38*I34 -> 28292.123
A40: Enterprise value | B40: =B37+B39 -> 35503.532
A41: Less total debt (FY2025) | B41: =B25 -> 46585
A42: Plus: cash and short-term investments (FY2025) | B42: ='Balance Sheet'!D4+'Balance Sheet'!D5 -> 37416
A43: Equity Value | B43: =B40-B41+B42 -> 26334.532
...

Sheet Comps
A1: Comparable Companies | B1: $ millions except per-share; market data as of 10.21.26; source Yahoo Finance
A3: Company | B3: Ticker | C3: Share price ($) | D3: Diluted shares (M) | E3: Market capitalization | F3: Total debt | G3: Cash and short-term investments | H3: Enterprise value | I3: Revenue, last twelve months | J3: EBITDA, last twelve months | K3: Net income, last twelve months | L3: EV / Revenue | M3: EV / EBITDA | N3: P / E
A4: Advanced Micro Devices, Inc. | B4: AMD | C4: 552.71 | D4: 1649.5 | E4: =C4*D4 -> 911695.15 | F4: 4280 | G4: 13110 | H4: =E4+F4-G4 -> 902865.15 | I4: 41310 | J4: 9560 | K4: 6470 | L4: =H4/I4 -> 21.85585 | M4: =H4/J4 -> 94.441961 | N4: =IF(K4>0,E4/K4,"n/m") -> 140.91115
A5: NVIDIA Corporation | B5: NVDA | C5: 221.97 | D5: 24397.5 | E5: =C5*D5 -> 5415513.1 | F5: 38860 | G5: 62470 | H5: =E5+F5-G5 -> 5391903.1 | I5: 302970 | J5: 201270 | K5: 192880 | L5: =H5/I5 -> 17.796822 | M5: =H5/J5 -> 26.789403 | N5: =IF(K5>0,E5/K5,"n/m") -> 28.077111
A6: Qualcomm Incorporated | B6: QCOM | C6: 177.96 | D6: 1067.5 | E6: =C6*D6 -> 189972.3 | F6: 1527 | G6: 830 | H6: =E6+F6-G6 -> 190669.3 | I6: 44070 | J6: 12000 | K6: 9260 | L6: =H6/I6 -> 4.3265101 | M6: =H6/J6 -> 15.889108 | N6: =IF(K6>0,E6/K6,"n/m") -> 20.515367
A7: Broadcom | B7: AVGO | C7: 337.8 | D7: 4885.25 | E7: =C7*D7 -> 1650237.4 | F7: 5942 | G7: 2398 | H7: =E7+F7-G7 -> 1653781.4 | I7: 89100 | J7: 52260 | K7: 38260 | L7: =H7/I7 -> 18.560959 | M7: =H7/J7 -> 31.645263 | N7: =IF(K7>0,E7/K7,"n/m") -> 43.132186
A8: Texas Instruments Incorporated | B8: TXN | C8: 284.65 | D8: 914.5 | E8: =C8*D8 -> 260312.42 | F8: 1405 | G8: 700 | H8: =E8+F8-G8 -> 261017.42 | I8: 19450 | J8: 9520 | K8: 6020 | L8: =H8/I8 -> 13.419919 | M8: =H8/J8 -> 27.417797 | N8: =IF(K8>0,E8/K8,"n/m") -> 43.241267
A9: Micron Technology Inc. | B9: MU | C9: 913.67 | D9: 1139.25 | E9: =C9*D9 -> 1040898.5 | F9: 5180 | G9: 43430 | H9: =E9+F9-G9 -> 1002648.5 | I9: 133190 | J9: 108840 | K9: 84970 | L9: =H9/I9 -> 7.5279567 | M9: =H9/J9 -> 9.2121329 | N9: =IF(K9>0,E9/K9,"n/m") -> 12.250189
A11: Median | L11: =MEDIAN(L4:L9) -> 15.60837 | M11: =MEDIAN(M4:M9) -> 27.1036 | N11: =MEDIAN(N4:N9) -> 35.604648
A12: Mean | L12: =AVERAGE(L4:L9) -> 13.914669 | M12: =AVERAGE(M4:M9) -> 34.232611 | N12: =AVERAGE(N4:N9) -> 48.021212
A14: Intel | B14: INTC | C14: =DCF!B22 -> 91.69 | D14: =DCF!B23 -> 4994 | E14: =C14*D14 -> 457899.86 | F14: =DCF!B25 -> 46585 | G14: =DCF!B42 -> 37416 | H14: =E14+F14-G14 -> 467068.86 | I14: ='Income Statement'!D2 -> 52853 | J14: ='Income Statement'!D9+'Cash Flow Statement'!D6+'Cash Flow Statement'!D9 -> 9492 | K14: ='Income Statement'!D16 -> -267 | L14: =H14/I14 -> 8.8371305 | M14: =H14/J14 -> 49.20658 | N14: =IF(K14>0,E14/K14,"n/m") -> n/m
A16: Implied Intel Valuation from peer median multiples
A17: Method | B17: Intel metric ($M) | C17: Peer median multiple | D17: Implied enterprise value | E17: Less: debt | F17: Plus: cash | G17: Implied equity value | H17: Implied value per share
A18: EV / EBITDA | B18: =J14 -> 9492 | C18: =M11 -> 27.1036 | D18: =B18*C18 -> 257267.37 | E18: =F14 -> 46585 | F18: =G14 -> 37416 | G18: =D18-E18+F18 -> 248098.37 | H18: =G18/D14 -> 49.679289
A19: EV / Revenue | B19: =I14 -> 52853 | C19: =L11 -> 15.60837 | D19: =B19*C19 -> 824949.2 | E19: =F14 -> 46585 | F19: =G14 -> 37416 | G19: =D19-E19+F19 -> 815780.2 | H19: =G19/D14 -> 163.35206
A21: P/E is not used: Intel's trailing earnings are negative.

Sheet Valuation Summary
A1: Valuation Summary: Intel value per share
A3: Method | B3: Value per share ($) | C3: Note
A4: DCF (WACC 15.3%, terminal growth 3.0%) | B4: =DCF!B45 -> 5.2732343 | C4: Base Case
A5: Comps: EV / EBITDA (peer median) | B5: =Comps!H18 -> 49.679289 | C5: Trailing
A6: Comps: EV / Revenue (peer median) | B6: =Comps!H19 -> 163.35206 | C6: Trailing
A7: Current share price | B7: =DCF!B22 -> 91.69 | C7: Market, Oct 21 2026
A8: DCF at 9.3% WACC (low discount rate) | B8: =DCF!E53 -> 14.479721 | C8: 9.3% WACC, 3.0% terminal growth

Sheet Checks
A1: Model Checks
A3: Check | B3: Value (should be 0) | C3: Pass (1 = yes)
A4: Balance sheet balances, all years | B4: {=SUMPRODUCT(ABS('Balance Sheet'!B39:I39))} -> 0 | C4: =IF(B4<0.5,1,0) -> 1
A5: Working capital ties to cash flow statement | B5: {=SUMPRODUCT(ABS('Working Capital'!E18:I18))} -> 5.4569682e-12 | C5: =IF(B5<0.5,1,0) -> 1
A6: Debt schedule ties to balance sheet | B6: {=ABS('Debt Schedule'!D10+SUMPRODUCT(ABS('Debt Schedule'!D14:I14)))} -> 0 | C6: =IF(B6<0.5,1,0) -> 1
A7: PP&E schedule ties to balance | B7: {=SUMPRODUCT(ABS('PP&E Schedule'!E12:I12))} -> 0 | C7: =IF(B7<0.5,1,0) -> 1
A8: Historical statements tie to the 10-K | B8: {=SUMPRODUCT(ABS('Income Statement'!B32:D35))+SUMPRODUCT(ABS('Balance Sheet'!B49:D54))+SUMPRODUCT(ABS('Cash Flow Statement'!B63:D68))} -> 0 | C8: =IF(B8<0.5,1,0) -> 1
A9: Share count rolls forward year to year | B9: {=SUMPRODUCT(ABS('Share Count'!F5:I5-'Share Count'!E8:H8))} -> 0 | C9: =IF(B9<0.5,1,0) -> 1
A10: WACC exceeds terminal growth (gap shown) | B10: =DCF!B32-DCF!B31 -> 0.12287327 | C10: =IF(B10>0,1,0) -> 1
A11: Valuation Summary ties to its sources | B11: =ABS('Valuation Summary'!B4-DCF!B45)+ABS('Valuation Summary'!B5-Comps!H18)+ABS('Valuation Summary'!B6-Comps!H19)+ABS('Valuation Summary'!B7-DCF!B22) -> 0 | C11: =IF(B11<0.5,1,0) -> 1
A12: Sensitivity inputs are at zero (model in normal state) | B12: =ABS(Sensitivity!B3)+ABS(Sensitivity!B4)+ABS(DCF!B29) -> 0 | C12: =IF(B12<0.000001,1,0) -> 1
A14: All checks | B14: =IF(SUM(C4:C12)=COUNT(C4:C12),"ALL CHECKS PASS","CHECK ERROR") -> ALL CHECKS PASS

Sheet Share Count
D1: FY2025 | E1: FY2026E | F1: FY2027E | G1: FY2028E | H1: FY2029E | I1: FY2030E | K1: FY2025 weighted average per the 10-K, used as the starting point.
A3: Dilution from stock-based compensation (% of beginning shares) | E3: 0.01 | F3: 0.01 | G3: 0.01 | H3: 0.01 | I3: 0.01
A5: Beginning shares (millions) | E5: =D8 -> 4994 | F5: =E8 -> 5043.94 | G5: =F8 -> 5094.3794 | H5: =G8 -> 5145.3232 | I5: =H8 -> 5196.7764
